Workbook
Name pl_lvl: 场景参数!$C$4
Name pl_techN: 场景参数!$C$5
Name pl_subN: 场景参数!$C$6
Name pl_dstN: 场景参数!$C$7
Name pl_leg: 场景参数!$C$8
Name pl_dmg: 场景参数!$C$9
Name pl_fireRate: 场景参数!$C$10
Name pl_multishot: 场景参数!$C$11
Name pl_echoMult: 场景参数!$C$12
Name pl_crit: 场景参数!$C$13
Name pl_range: 场景参数!$C$14
Name pl_dmgTaken: 场景参数!$C$15
Name pl_lvlWeapon: 场景参数!$C$17
Name pl_lvlMult: 场景参数!$C$18
Name boss_hp: 场景参数!$C$19
Name boss_rageT: 场景参数!$C$20
Name boss_shieldPct: 场景参数!$C$21
Name boss_dmgTakenRage: 场景参数!$C$23
Name levelNeed_base: 场景参数!$C$25
Name trial_xp_disc: 场景参数!$C$26

Sheet README
A1: 牛马大逃杀 · v18 全部游戏元素参考表
A3: 生成日期 | B3: 2026-07-04(v18, Batch 1+2 完整含 proc 框架)
A4: 数据来源 | B4: src/game/data/*.js + core.js + constants.js 逐条读取
A5: 用法 | B5: 直接改"场景参数"表格里蓝色 数字，其他所有 DPS/时间/评估 会自动重算
A7: 颜色约定
A8: · 蓝色数字 | B8: 用户可改的场景参数(调这些看不同结论)
A9: · 黑色数字 | B9: Excel 公式计算的结果
A10: · 绿色单元格 | B10: 跨表引用
A11: · 红色文字 | B11: 警告 / 已知失衡
A12: · 黄色底纹 | B12: 关键假设，值得注意
A13: · 淡红底纹 | B13: 当前已发现的失衡组合
A14: · 淡绿底纹 | B14: 数值健康
A16: 分页说明
A17: 场景参数 | B17: 玩家 build 假设 + Boss 血量公式 + Level 常量
A18: 主武器 | B18: 17 把 WEAPONS + 6 传说 LEGENDS，含 DPS 计算与击杀时间
A19: 副武器 | B19: 11 件 SUBS，含 3 级伤害
A20: 主动技能 | B20: 8 个 ACTIVES，含 3 级 cd/效果
A21: 被动技能 | B21: 45 个 SKILLS，按 base/optimizer/slacker/proc 分组
A22: 技术模组 | B22: 13 个 TECH，3 档 tier 数值
A23: 蒸馏池 | B23: 6 种 DISTILLS
A24: 诅咒 | B24: 4 种 CURSES
A25: Proc 效果 | B25: 8 种 proc + 触发概率复合
A26: 消耗品 | B26: 10 种 CONSUMABLES
A27: 觉醒配方 | B27: 4 组 EVOLUTIONS
A28: 精英怪 | B28: 10 只 ELITES(T1×4 + T2×6)
... A30: 失衡分析 | B30: DPS/生存/爆发时间的组合分析与 bug 组合发现

Sheet 场景参数
A1: 场景参数（改蓝色数字，其他表所有 DPS/击杀时间会自动重算）
A3: 分类 | B3: 参数 | C3: 值 | D3: 说明
A4: 玩家等级/build | B4: 玩家等级 | C4: 15 | D4: 默认满 build 15 级
B5: techN 模组累计层数 | C5: 12 | D5: techN = sum(pl.tech)，满 build 约 12
B6: subN 副武器累计等级 | C6: 9 | D6: subN = sum(subs.lv)，3件 Lv.3 = 9
B7: dstN 蒸馏累计条数 | C7: 2 | D7: dstN = Object.keys(pl.distills).length
B8: 传说武器 | C8: 1 | D8: 0=否, 1=是
B9: mods.dmg | C9: 2.167 | D9: 卷王 ×3 × Ultra Finetune ×2 = 1.728 × 1.2544
B10: mods.fireRate | C10: 4.062 | D10: 996 + Ultra Quant + Ultra KV + Ultra Finetune
B11: mods.multishot | C11: 2 | D11: Ultra Fewshot ×2
B12: mods.echoMult(v18 fix) | C12: 0.733 | D12: v18 软上限 0.4+0.5×(1-1/(1+multishot))
B13: mods.crit | C13: 0.57 | D13: Ultra Temp ×3 = 57%
B14: mods.range | C14: 1.35 | D14: Ultra Ctxwin ×2 = 1.35
B15: mods.dmgTaken | C15: 1 | D15: 受伤系数（<1 就减伤）
B16: 武器等级 | C16: 5 | D16: 主武器 1-5 级
B17: lvlMult(标准1.3^(lvl-1)) | C17: 5 | D17: 武器等级伤害乘子 = 1.3^(lvl-1) for 标准 / 1.15 for drone / 1 for 传说
C18: =1.3^(C17-1)
A19: Boss 血量公式 | B19: v18 Boss HP | C19: =(900 + 600 + 60*C4 + 180*C5 + 220*C6 + 280*C7 + 400*C8) * (1 + 0.15*C7) | D19: (900 + 600 + 60×lvl + 180×techN + 220×subN + 280×dstN + 400×leg) × (1+0.15×dstN)
B20: Boss 狂暴阈值 | C20: 0.75 | D20: v18 修正为 0.75（原 0.5）
B21: Boss 狂暴护盾比例 | C21: 0.15 | D21: maxHp × 0.15
B22: Boss 狂暴护盾时长(秒) | C22: 8
B23: Boss 狂暴期 dmgTaken 乘子 | C23: 0.7 | D23: v18 减伤 30%
A25: 升级曲线 | B25: levelNeed 底数 | C25: 1.22 | D25: v18 从 1.26 回调到 1.22
B26: 试用期 XP 折扣 | C26: 0.55 | D26: v18 从 0.42 上调到 0.55
B27: xpPerKill(正式赛) | C27: 12
A29: 射速软上限 | B29: fireRateOf 转折点 | C29: 2 | D29: 公式：f<=2→f; f>2→2+sqrt(f-2)×0.6

Sheet 主武器
A1: ID | B1: 名称 | C1: 国 | D1: kind | E1: cd(s) | F1: 每发伤害 | G1: 弹速 | H1: 基础射程 | I1: DPS 基础(每发/cd) | J1: 有效射速(软上限) | K1: 每发伤害×lvlMult×模组×echo | L1: 暴击期望乘子 | M1: 有效周期(秒) | N1: 有效 DPS(满 build) | O1: 满 build 击杀 Boss 秒数 | P1: 自动追踪 | Q1: kind 特殊 | R1: 备注
A2: deepseek | B2: DeepSeek | C2: CN | D2: mg | E2: 0.11 | F2: 2.3 | G2: 300 | H2: 220 | I2: =IF(E2>0, F2/E2, F2*4) | J2: =IF(pl_fireRate<=2, pl_fireRate, 2+SQRT(pl_fireRate-2)*0.6) | K2: =F2*pl_dmg*pl_lvlMult*(1 + pl_multishot*pl_echoMult) | L2: =1 + pl_crit | M2: =E2 / J2 | N2: =K2*L2/M2 | O2: =IF(N2>0, boss_hp/N2, "N/A") | P2: 否 | Q2: spread 0.07
A3: kimi | B3: Kimi | C3: CN | D3: sniper | E3: 1.5 | F3: 30 | G3: 620 | H3: 600 | I3: =IF(E3>0, F3/E3, F3*4) | J3: =IF(pl_fireRate<=2, pl_fireRate, 2+SQRT(pl_fireRate-2)*0.6) | K3: =F3*pl_dmg*pl_lvlMult*(1 + pl_multishot*pl_echoMult) | L3: =1 + pl_crit | M3: =E3 / J3 | N3: =K3*L3/M3 | O3: =IF(N3>0, boss_hp/N3, "N/A") | P3: 否 | Q3: pierce 99 穿墙
A4: qwen | B4: 通义千问 | C4: CN | D4: shotgun | E4: 1.1 | F4: 23 | G4: 260 | H4: 125 | I4: =IF(E4>0, F4/E4, F4*4) | J4: =IF(pl_fireRate<=2, pl_fireRate, 2+SQRT(pl_fireRate-2)*0.6) | K4: =F4*pl_dmg*pl_lvlMult*(1 + pl_multishot*pl_echoMult) | L4: =1 + pl_crit | M4: =E4 / J4 | N4: =K4*L4/M4 | O4: =IF(N4>0, boss_hp/N4, "N/A") | P4: 否 | Q4: 5发扇形 spread 1.0 | R4: 每发伤害=单弹×count
A5: wenxin | B5: 文心一言 | C5: CN | D5: lob | E5: 1.4 | F5: 26 | G5: 190 | H5: 190 | I5: =IF(E5>0, F5/E5, F5*4) | J5: =IF(pl_fireRate<=2, pl_fireRate, 2+SQRT(pl_fireRate-2)*0.6) | K5: =F5*pl_dmg*pl_lvlMult*(1 + pl_multishot*pl_echoMult) | L5: =1 + pl_crit | M5: =E5 / J5 | N5: =K5*L5/M5 | O5: =IF(N5>0, boss_hp/N5, "N/A") | P5: 否 | Q5: 落点爆炸 boomR 42
A6: doubao | B6: 豆包 | C6: CN | D6: homing | E6: 0.7 | F6: 12.5 | G6: 185 | H6: 560 | I6: =IF(E6>0, F6/E6, F6*4) | J6: =IF(pl_fireRate<=2, pl_fireRate, 2+SQRT(pl_fireRate-2)*0.6) | K6: =F6*pl_dmg*pl_lvlMult*(1 + pl_multishot*pl_echoMult) | L6: =1 + pl_crit | M6: =E6 / J6 | N6: =K6*L6/M6 | O6: =IF(N6>0, boss_hp/N6, "N/A") | P6: 是 | Q6: homing 4.5
A7: glm | B7: 智谱GLM | C7: CN | D7: chain | E7: 1 | F7: 17 | G7: 0 | H7: 190 | I7: =IF(E7>0, F7/E7, F7*4) | J7: =IF(pl_fireRate<=2, pl_fireRate, 2+SQRT(pl_fireRate-2)*0.6) | K7: =F7*pl_dmg*pl_lvlMult*(1 + pl_multishot*pl_echoMult) | L7: =1 + pl_crit | M7: =E7 / J7 | N7: =K7*L7/M7 | O7: =IF(N7>0, boss_hp/N7, "N/A") | P7: 就近 | Q7: 链跳 3 目标 decay 0.8
A8: chatgpt | B8: ChatGPT | C8: US | D8: single | E8: 0.5 | F8: 10 | G8: 320 | H8: 260 | I8: =IF(E8>0, F8/E8, F8*4) | J8: =IF(pl_fireRate<=2, pl_fireRate, 2+SQRT(pl_fireRate-2)*0.6) | K8: =F8*pl_dmg*pl_lvlMult*(1 + pl_multishot*pl_echoMult) | L8: =1 + pl_crit | M8: =E8 / J8 | N8: =K8*L8/M8 | O8: =IF(N8>0, boss_hp/N8, "N/A") | P8: 否 | Q8: 标准单发
A9: claude | B9: Claude | C9: US | D9: charge | E9: 0.45 | F9: 42 | G9: 0 | H9: 270 | I9: =IF(E9>0, F9/E9, F9*4) | J9: =IF(pl_fireRate<=2, pl_fireRate, 2+SQRT(pl_fireRate-2)*0.6) | K9: =F9*pl_dmg*pl_lvlMult*(1 + pl_multishot*pl_echoMult) | L9: =1 + pl_crit | M9: =(1.2 + E9) / J9 | N9: =K9*L9/M9 | O9: =IF(N9>0, boss_hp/N9, "N/A") | P9: 否 | Q9: 蓄力 1.2s / dmgMax=42 | R9: dmg 用蓄满值
A10: gemini | B10: Gemini | C10: US | D10: twin | E10: 0.55 | F10: 12 | G10: 320 | H10: 240 | I10: =IF(E10>0, F10/E10, F10*4) | J10: =IF(pl_fireRate<=2, pl_fireRate, 2+SQRT(pl_fireRate-2)*0.6) | K10: =F10*pl_dmg*pl_lvlMult*(1 + pl_multishot*pl_echoMult) | L10: =1 + pl_crit | M10: =E10 / J10 | N10: =K10*L10/M10 | O10: =IF(N10>0, boss_hp/N10, "N/A") | P10: 否 | Q10: 双联平行 | R10: 每发伤害=6×2
A11: copilot | B11: Copilot | C11: US | D11: drone | E11: 0.8 | F11: 8.5 | G11: 300 | H11: 150 | I11: =IF(E11>0, F11/E11, F11*4) | J11: =IF(pl_fireRate<=2, pl_fireRate, 2+SQRT(pl_fireRate-2)*0.6) | K11: =F11*pl_dmg*1.15^(pl_lvlWeapon-1)*(1 + pl_multishot*pl_echoMult) | L11: =1 + pl_crit | M11: =E11 / J11 | N11: =K11*L11/M11 | O11: =IF(N11>0, boss_hp/N11, "N/A") | P11: 是 | Q11: 2 僚机(满级3) | R11: 僚机独立开火
A12: midjourney | B12: Midjourney | C12: US | D12: gacha | E12: 0.9 | F12: 10 | G12: 300 | H12: 230 | I12: =IF(E12>0, F12/E12, F12*4) | J12: =IF(pl_fireRate<=2, pl_fireRate, 2+SQRT(pl_fireRate-2)*0.6) | K12: =F12*pl_dmg*pl_lvlMult*(1 + pl_multishot*pl_echoMult) | L12: =1 + pl_crit | M12: =E12 / J12 | N12: =K12*L12/M12 | O12: =IF(N12>0, boss_hp/N12, "N/A") | P12: 部分 | Q12: 抽卡 4 模式，0.5-3× 浮动 | R12: dmg 取平均
A13: grok | B13: Grok | C13: US | D13: boomerang | E13: 0.95 | F13: 10 | G13: 300 | H13: 140 | I13: =IF(E13>0, F13/E13, F13*4) | J13: =IF(pl_fireRate<=2, pl_fireRate, 2+SQRT(pl_fireRate-2)*0.6) | K13: =F13*pl_dmg*pl_lvlMult*(1 + pl_multishot*pl_echoMult) | L13: =1 + pl_crit | M13: =E13 / J13 | N13: =K13*L13/M13 | O13: =IF(N13>0, boss_hp/N13, "N/A") | P13: 否 | Q13: 去回程双判
A14: meta | B14: Meta Llama(v18) | C14: US | D14: aura | E14: 0.25 | F14: 6 | G14: 0 | H14: 70 | I14: =IF(E14>0, F14/E14, F14*4) | J14: =IF(pl_fireRate<=2, pl_fireRate, 2+SQRT(pl_fireRate-2)*0.6) | K14: =F14*pl_dmg*pl_lvlMult*(1 + pl_multishot*pl_echoMult) | L14: =1 + pl_crit | M14: =E14 / J14 | N14: =K14*L14/M14 | O14: =IF(N14>0, boss_hp/N14, "N/A") | P14: 全命中 | Q14: tickCd 0.25s | R14: DPS=dmg/tickCd
A15: minimax | B15: MiniMax(v18) | C15: CN | D15: totem | E15: 2.5 | F15: 8 | G15: 0 | H15: 190 | I15: =IF(E15>0, F15/E15, F15*4) | J15: =IF(pl_fireRate<=2, pl_fireRate, 2+SQRT(pl_fireRate-2)*0.6) | K15: =F15*pl_dmg*pl_lvlMult*(1 + pl_multishot*pl_echoMult) | L15: =1 + pl_crit | M15: =0.55 / J15 / 3 | N15: =K15*L15/M15 | O15: =IF(N15>0, boss_hp/N15, "N/A") | P15: 炮台自动 | Q15: 最多3座 shotCd 0.55 | R15: DPS ≈ 3×dmg/shotCd
A16: moonshot | B16: 月之暗面(v18) | C16: CN | D16: mine | E16: 0.5 | F16: 18 | G16: 0 | H16: 22 | I16: =IF(E16>0, F16/E16, F16*4) | J16: =IF(pl_fireRate<=2, pl_fireRate, 2+SQRT(pl_fireRate-2)*0.6) | K16: =F16*pl_dmg*pl_lvlMult*(1 + pl_multishot*pl_echoMult) | L16: =1 + pl_crit | M16: =E16 / J16 | N16: =K16*L16/M16 | O16: =IF(N16>0, boss_hp/N16, "N/A") | P16: 踩到才触发 | Q16: fuseT 1.5
A17: zhipu | B17: 智谱清言(v18) | C17: CN | D17: summon | E17: 6 | F17: 6 | G17: 0 | H17: 180 | I17: =IF(E17>0, F17/E17, F17*4) | J17: =IF(pl_fireRate<=2, pl_fireRate, 2+SQRT(pl_fireRate-2)*0.6) | K17: =F17*pl_dmg*pl_lvlMult*(1 + pl_multishot*pl_echoMult) | L17: =1 + pl_crit | M17: =0.8 / J17 / 3 / 0.4 | N17: =K17*L17/M17 | O17: =IF(N17>0, boss_hp/N17, "N/A") | P17: 实习生自动 | Q17: 3 只 15s shotCd 0.8 | R17: DPS ≈ 3×6/0.8
A18: baichuan | B18: 百川智能(v18) | C18: CN | D18: field | E18: 4.5 | F18: 0 | G18: 0 | H18: 220 | I18: =IF(E18>0, F18/E18, F18*4) | J18: =IF(pl_fireRate<=2, pl_fireRate, 2+SQRT(pl_fireRate-2)*0.6) | K18: =F18*pl_dmg*pl_lvlMult*(1 + pl_multishot*pl_echoMult) | L18: =1 + pl_crit | M18: =1 | N18: =22*pl_dmg*pl_lvlMult*L18 | O18: =IF(N18>0, boss_hp/N18, "N/A") | P18: 全命中 | Q18: dps 22 life 9s slow 0.4 | R18: DPS = 22 直接

Sheet 传说武器
A1: ID | B1: 名称 | C1: kind | D1: 基础 cd | E1: 每发伤害 | F1: 射程 | G1: 融合配方 | H1: 有效 DPS(近似) | I1: 击杀 Boss 秒数 | J1: 真质变? | K1: 备注
A2: agi | B2: AGI降临 | C2: leg_agi | D2: 0.12 | E2: 5.5 | F2: 320 | G2: DeepSeek+ChatGPT | H2: =E2*(1+pl_crit)*pl_dmg/D2 | I2: =boss_hp/H2 | J2: 否 | K2: 天罚 60 每 3s + 常规追踪弹
A3: price_war | B3: 百模大战·价格屠夫 | C3: leg_pea | D3: 0.5 | E3: 48 | F3: 280 | G3: 通义+豆包 | H3: =E3*(1+pl_crit)*pl_dmg/D3 | I3: =boss_hp/H3 | J3: 否 | K3: 15发追踪豆
A4: tenx | B4: 十倍程序员 | C4: leg_drone | D4: 1.2 | E4: 113 | F4: 170 | G4: Claude+Copilot | H4: =E4*(1+pl_crit)*pl_dmg/D4 | I4: =boss_hp/H4 | J4: 否 | K4: 4 僚机+齐射
A5: pie_feast | B5: 画饼充饥 | C5: leg_pie | D5: 1.5 | E5: 36 | F5: 210 | G5: 文心+MJ | H5: =E5*(1+pl_crit)*pl_dmg/D5 | I5: =boss_hp/H5 | J5: 是 | K5: 燃烧地带 10dps×5s
A6: infinite_ctx | B6: 无限上下文 | C6: leg_beam | D6: 0.12 | E6: 6 | F6: 9999 | G6: Kimi+Gemini | H6: =E6*(1+pl_crit)*pl_dmg/D6 | I6: =boss_hp/H6 | J6: 否 | K6: 按住持续激光
A7: mouthpiece | B7: 职场嘴替 | C7: leg_boom | D7: 1.3 | E7: 66 | F7: 200 | G7: GLM+Grok | H7: =E7*(1+pl_crit)*pl_dmg/D7 | I7: =boss_hp/H7 | J7: 否 | K7: X回旋镖+链电 zap

Sheet 副武器
A1: ID | B1: 名称 | C1: persona | D1: 触发方式 | E1: cd(s) | F1: Lv.1 伤害 | G1: Lv.2 伤害 | H1: Lv.3 伤害 | I1: 半径/射程 | J1: 自动追踪 | K1: Lv.3 单体 DPS | L1: 备注
A2: keyboard | B2: 机械键盘 | C2: 通用 | D2: 贴身近战扇形 | E2: 1.6 | F2: 14 | G2: 20 | H2: 28 | I2: 90 扇形 | J2: 就近 | K2: =IF(E2>0, H2/E2, IF(H2>0, H2, 0))
A3: stapler | B3: 订书机炮台 | C3: 通用 | D3: 部署炮台 | E3: 6 | F3: 6 | G3: 9 | H3: 12 | I3: 170 索敌 | J3: 炮台自动 | K3: =IF(E3>0, H3/E3, IF(H3>0, H3, 0))
A4: monitor | B4: 显示器回旋盾 | C4: 通用 | D4: 环绕撞击 | E4: 0 | F4: 10 | G4: 14 | H4: 18 | I4: 34 环绕 | J4: 全环命中 | K4: =IF(E4>0, H4/E4, IF(H4>0, H4, 0))
A5: mug | B5: 马克杯流星锤 | C5: 通用 | D5: 甩杯 AOE | E5: 2.2 | F5: 16 | G5: 24 | H5: 34 | I5: 230 索敌 | J5: 就近 | K5: =IF(E5>0, H5/E5, IF(H5>0, H5, 0))
A6: shredder | B6: 碎纸机光环 | C6: 通用 | D6: 贴身持续 | E6: 0 | F6: 8 | G6: 12 | H6: 17 | I6: 56 半径 | J6: 全范围命中 | K6: =IF(E6>0, H6/E6, IF(H6>0, H6, 0))
A7: laserpen | B7: 会议激光笔 | C7: 通用 | D7: 穿透射线 | E7: 3.2 | F7: 22 | G7: 32 | H7: 46 | I7: 270 | J7: 就近 | K7: =IF(E7>0, H7/E7, IF(H7>0, H7, 0))
A8: oa_form | B8: OA审批流公文包 | C8: optimizer | D8: 命中减速+延迟引爆 | E8: 2.6 | F8: 8 | G8: 12 | H8: 17 | I8: 220 索敌 | J8: 就近 | K8: =IF(E8>0, H8/E8, IF(H8>0, H8, 0))
A9: fire_sprinkler | B9: 消防警报喷淋 | C9: optimizer | D9: 部署减速区 | E9: 8 | F9: 6 | G9: 9 | H9: 13 | I9: 70 半径 | J9: 全范围命中 | K9: =IF(E9>0, H9/E9, IF(H9>0, H9, 0))
A10: meeting_room | B10: 会议室预定表 | C10: optimizer | D10: 部署灼烧区 | E10: 9 | F10: 3 | G10: 5 | H10: 7 | I10: 66 半径 | J10: 全范围命中 | K10: =IF(E10>0, H10/E10, IF(H10>0, H10, 0))
A11: online_badge | B11: 在线状态徽章 | C11: slacker | D11: 移动中标记+引爆 | E11: 0.6 | F11: 0 | G11: 0 | H11: 0 | I11: 90 | J11: 概率标记 | K11: =IF(E11>0, H11/E11, IF(H11>0, H11, 0))
A12: fitness_ring | B12: 健身环挑战 | C12: slacker | D12: 移动尾迹定身圈 | E12: 1.4 | F12: 0 | G12: 0 | H12: 0 | I12: 48 半径 | J12: 尾迹 | K12: =IF(E12>0, H12/E12, IF(H12>0, H12, 0))

Sheet 主动技能
A1: ID | B1: 名称 | C1: persona | D1: Lv.1 cd | E1: Lv.2 cd | F1: Lv.3 cd | G1: 效果概述 | H1: Lv.3 秒数值 | I1: 备注
A2: blink | B2: 摸鱼瞬移 | C2: 通用 | D2: 9 | E2: 7 | F2: 5 | G2: 向移动方向瞬移 | H2: 185px
A3: layoff | B3: 裁员通知 | C3: 通用 | D3: 12 | E3: 10 | F3: 8 | G3: 贯穿光束 dmg + maxHp% | H3: 80 + 12%maxHp(Boss上限150)
A4: bing_shield | B4: 画饼护盾 | C4: 通用 | D4: 16 | E4: 13 | F4: 10 | G4: 短时无敌 | H4: 2.0s 无敌
A5: teambuild | B5: 团建号召 | C5: 通用 | D5: 14 | E5: 11 | F5: 9 | G5: 拽拉眩晕+易伤 | H5: 230 半径
A6: force_mute | B6: 强制五分钟静音 | C6: optimizer | D6: 14 | E6: 12 | F6: 10 | G6: 扇形眩晕+减速 | H6: 240 扇形
A7: linked_fate | B7: 花名册点对点连坐 | C7: optimizer | D7: 20 | E7: 17 | F7: 14 | G7: 锁链拉扯 | H7: 全场就近 2 敌 8s
A8: temp_offline | B8: 临时下线 | C8: slacker | D8: 11 | E8: 9 | F8: 7 | G8: 隐身+无敌+穿墙冲刺 | H8: 1.6s
A9: slack_appeal | B9: 摸鱼申诉信 | C9: slacker | D9: 22 | E9: 18 | F9: 15 | G9: 真摸鱼回血+免死 | H9: 40%maxHp + 1 免死

Sheet 被动技能
A1: ID | B1: 名称 | C1: max | D1: rarity | E1: persona | F1: group | G1: 效果 | H1: 标签
A2: moyu_master | B2: 摸鱼学大师 | C2: 3 | D2: 白 | E2: 通用 | F2: 移速 | G2: 移速 +15%/层
A3: paid_toilet | B3: 带薪如厕 | C3: 2 | D3: 白 | E3: 通用 | F3: 回复 | G3: 站定1s后每秒回3HP/层
A4: pua_immunity | B4: PUA免疫 | C4: 3 | D4: 白 | E4: 通用 | F4: 减伤 | G4: 受伤 -20%/层
A5: manage_up | B5: 向上管理 | C5: 3 | D5: 白 | E5: 通用 | F5: 经验 | G5: 经验 +25%/层
A6: resume_gilding | B6: 简历镀金 | C6: 1 | D6: 绿 | E6: 通用 | F6: 生命 | G6: 升级+10最大HP
A7: fubao_996 | B7: 996福报 | C7: 2 | D7: 绿 | E7: 通用 | F7: 射速 | G7: 射速+25%/层 但最大HP-10 | H7: 双刃剑
A8: huabing | B8: 画饼充饥 | C8: 2 | D8: 绿 | E8: 通用 | F8: 回复 | G8: 击杀回10HP/层
A9: early_leave | B9: 提前下班 | C9: 2 | D9: 蓝 | E9: 通用 | F9: 位移 | G9: 解锁Shift冲刺+冲刺后+40%射速
A10: side_hustle | B10: 副业变现 | C10: 1 | D10: 蓝 | E10: 通用 | F10: 资源 | G10: 击杀30%概率掉消耗品
A11: juanwang | B11: 卷王之王 | C11: 3 | D11: 白 | E11: 通用 | F11: 伤害 | G11: 子弹伤害 +20%/层
A12: quit_threat | B12: 离职威胁 | C12: 1 | D12: 绿 | E12: 通用 | F12: 低血 | G12: HP<30%时移速+30%
A13: n_plus_one | B13: N+1谈判专家 | C13: 1 | D13: 紫 | E13: 通用 | F13: 免死 | G13: 死亡原地复活50%HP(一次)
A14: weekly_report | B14: 周报生成器 | C14: 2 | D14: 白 | E14: 通用 | F14: 经验 | G14: 每秒+1经验/层
A15: desk_fengshui | B15: 工位风水学 | C15: 2 | D15: 白 | E15: 通用 | F15: 生命 | G15: 最大HP+30/层
A16: invisible_worker | B16: 办公室小透明 | C16: 1 | D16: 蓝 | E16: 通用 | F16: 仇恨 | G16: 敌人索敌范围-30%
A17: blame_master | B17: 甩锅大师 | C17: 2 | D17: 蓝 | E17: 通用 | F17: 闪避 | G17: 20%概率完全闪避/层
A18: instant_reply | B18: 已读秒回 | C18: 2 | D18: 绿 | E18: 通用 | F18: 弹速 | G18: 弹速+30%/层 | H18: 部分武器不适用
A19: company_wool | B19: 薅公司羊毛 | C19: 1 | D19: 蓝 | E19: 通用 | F19: 资源 | G19: 消耗品效果+50%
A20: skip_report | B20: 越级汇报 | C20: 2 | D20: 绿 | E20: 通用 | F20: 穿透 | G20: 穿透+1/层 | H20: 部分武器不适用
A21: toxic_aura | B21: 职场毒瘤 | C21: 3 | D21: 蓝 | E21: 通用 | F21: AoE | G21: 身边100px每秒-2HP/层
A22: office_politics | B22: 办公室政治 | C22: 5 | D22: 白 | E22: optimizer | F22: 溅射 | G22: 命中12%/层挂内耗，1.5s溅射30%
A23: meeting_wait | B23: 3秒发言等待区 | C23: 5 | D23: 白 | E23: optimizer | F23: 减速 | G23: 减速强度+8%/层
A24: recycle_cooldown | B24: 回收站冷静期 | C24: 3 | D24: 绿 | E24: optimizer | F24: 控场 | G24: 眩晕后目标2s内受伤+15%/层
A25: guilt_by_association | B25: 连坐制度 | C25: 3 | D25: 绿 | E25: optimizer | F25: 传染 | G25: 眩晕25%/层概率传染
A26: kpi_countdown | B26: 季度考核倒计时 | C26: 3 | D26: 蓝 | E26: optimizer | F26: 正反馈 | G26: 每受控敌人+2%全属性/层 | H26: 20层上限
A27: circuit_breaker | B27: 熔断机制 | C27: 1 | D27: 蓝 | E27: optimizer | F27: 独特 | G27: 受重击触发全屏1.2s眩晕+0.6s免疫 | H27: 20s CD
A28: blame_reflect | B28: 甩锅式反伤 | C28: 1 | D28: 紫 | E28: optimizer | F28: 质变 | G28: 40%概率完全转移伤害给受控敌人 | H28: 觉醒→80%
A29: bottom_elimination | B29: 末位淘汰制 | C29: 1 | D29: 紫 | E29: optimizer | F29: 质变 | G29: 8s一次约谈最低HP敌人，定身2s爆炸 | H29: v18 cap 250
A30: assembly_nuke | B30: 全员大会核爆 | C30: 1 | D30: 橙 | E30: optimizer | F30: 大招 | G30: 30积分触发全屏350%攻击 | H30: Boss上限300
A31: mouse_jiggler | B31: 鼠标晃动器 | C31: 5 | D31: 白 | E31: slacker | F31: 移速 | G31: 移速+10%/层
A32: online_response | B32: 线上响应术 | C32: 5 | D32: 白 | E32: slacker | F32: 减伤 | G32: 连续移动2s后受伤-15%/层
A33: fake_busy | B33: 假装忙碌 | C33: 3 | D33: 绿 | E33: slacker | F33: 触发 | G33: 闲置1.5s触发提速20%
A34: read_no_reply_school | B34: 已读不回学 | C34: 3 | D34: 绿 | E34: slacker | F34: 闪避 | G34: 闪避成功后移速+12%/层 1s
A35: uptime_cert | B35: 在线时长认证 | C35: 3 | D35: 蓝 | E35: slacker | F35: 正反馈 | G35: 连续不被命中每5s一层活跃认证 | H35: 上限5
A36: never_offline | B36: 永不下线 | C36: 1 | D36: 蓝 | E36: slacker | F36: 独特 | G36: 闪避+18%(上限90%)最大HP-15 | H36: 双刃剑
A37: fake_diligence | B37: 假勤奋，真怠工 | C37: 1 | D37: 紫 | E37: slacker | F37: 质变 | G37: 不受伤8s触发全屏(v18 池上限wpnDmg×8)
A38: perpetual_slack | B38: 永动摸鱼引擎 | C38: 1 | D38: 橙 | E38: slacker | F38: 大招 | G38: 移800px触发2s免疫+10s冷却 | H38: v18 大幅收紧
A39: proc_fire_enchant | B39: 火焰附魔·数据泄漏 | C39: 3 | D39: 蓝 | E39: 通用 | F39: proc | G39: onHit 20%/层 燃烧4dps×2s | H39: v18
A40: proc_ice_enchant | B40: 冰霜附魔·系统卡顿 | C40: 3 | D40: 蓝 | E40: 通用 | F40: proc | G40: onHit 25%/层 减速40%×1.5s | H40: v18
...

Sheet 技术模组
A1: ID | B1: 名称 | C1: max | D1: PLAYER_ONLY | E1: 标准 | F1: Pro | G1: Ultra | H1: 备注
A2: fewshot | B2: 少样本提示 | C2: 2 | D2: 是 | E2: multishot+1;echoMult 0.4+0.5×(1-1/(1+m)) | F2: 同左 | G2: 同左 | H2: v18 fix：软上限
A3: cot | B3: 思维链 | C3: 2 | D3: 否 | E3: pierce+1 | F3: pierce+1 | G3: pierce+2
A4: temp | B4: 温度调高 | C4: 3 | D4: 是 | E4: crit+10% | F4: +14% | G4: +19%
A5: quant | B5: INT4量化 | C5: 2 | D5: 否 | E5: fireRate/bulletSpd×1.10 | F5: ×1.15 | G5: ×1.22
A6: attention | B6: 注意力机制 | C6: 2 | D6: 是 | E6: homing+0.8 | F6: +1.1 | G6: +1.5
A7: kvcache | B7: KV缓存 | C7: 2 | D7: 否 | E7: fireRate×1.08 | F7: ×1.12 | G7: ×1.18
A8: finetune | B8: 私有微调 | C8: 2 | D8: 否 | E8: dmg/fireRate×1.05 移速×1.03 | F8: ×1.08/1.05 | G8: ×1.12/1.08
A9: ctxwin | B9: 上下文扩容 | C9: 2 | D9: 否 | E9: range×1.18 | F9: ×1.25 | G9: ×1.35
A10: sysprompt | B10: 系统提示 | C10: 1 | D10: 否 | E10: 10护盾 | F10: 15 | G10: 22 | H10: 每45s补盾
A11: rag | B11: 检索增强 RAG | C11: 2 | D11: 否 | E11: rag+1 | F11: +0.15伤害 | G11: +0.35伤害
A12: inject | B12: 提示注入 | C12: 99 | D12: 否 | E12: 策反12s | F12: 20s | G12: 30s | H12: instant
A13: clear | B13: /clear清空上下文 | C13: 99 | D13: 否 | E13: r=70 dmg=22 | F13: r=95 dmg=30 | G13: r=125 dmg=42 | H13: instant
A14: distill | B14: 大模型蒸馏 | C14: 99 | D14: 是 | E14: 随机蒸馏一个 Boss 技能 | H14: instant

Sheet 蒸馏池
A1: ID | B1: 名称 | C1: cd(s) | D1: 源 | E1: 效果
A2: ppt | B2: 全屏演示·mini | C2: 10 | D2: PPT 大师 | E2: 向准星光锥，高伤害+眩晕
A3: snitch | B3: 打小报告·mini | C3: 14 | D3: 小报告专家 | E3: 举报最近敌人，全场围殴
A4: pie | B4: 画大饼·mini | C4: 8 | D4: 老板 | E4: 甩出 6 张小饼
A5: upman | B5: 向上管理·mini | C5: 10 | D5: 向上管理大师 | E5: 自赋能3s+25%伤害+15%移速+回6血
A6: align | B6: 对齐立场·mini | D6: 对齐守卫 | E6: 25%概率挡下正面子弹
A7: pua | B7: PUA冲击·mini | C7: 9 | D7: 老板 | E7: 震开身边+小伤害

Sheet 诅咒
A1: ID | B1: 名称 | C1: 效果 | D1: 可否施加于敌
A2: hallu | B2: 幻觉 | C2: 准星漂移，看啥都不真 | D2: 否
A3: overfit | B3: 过拟合 | C3: 移速大减、禁冲刺 | D3: 否
A4: repeat | B4: 复读机 | C4: 弹道锁死方向 | D4: 否
A5: overflow | B5: 上下文溢出 | C5: 射速大减 | D5: 否

Sheet Proc 效果
A1: 效果 | B1: hook | C1: 来源技能 | D1: 基础触发率(每层) | E1: max 层 | F1: 满级总触发率 | G1: 效果参数 | H1: 备注
A2: burn | B2: onHit | C2: 火焰附魔·数据泄漏 | D2: 0.2 | E2: 3 | F2: =1 - (1-D2)^E2 | G2: 4 dps × 2s
A3: chill | B3: onHit | C3: 冰霜附魔·系统卡顿 | D3: 0.25 | E3: 3 | F3: =1 - (1-D3)^E3 | G3: 减速40% × 1.5s
A4: shock | B4: onCrit | C4: 雷电附魔·断电通知 | D4: 0.4 | E4: 3 | F4: =1 - (1-D4)^E4 | G4: 链电3目标每链5 | H4: 需暴击
A5: poison | B5: onHit | C5: 毒液附魔·PUA后遗症 | D5: 0.3 | E5: 3 | F5: =1 - (1-D5)^E5 | G5: 2 dps × 3s
A6: heal | B6: onHit | C6: 吸血附魔·画饼实体化 | D6: 0.5 | E6: 3 | F6: =1 - (1-D6)^E6 | G6: 回2血
A7: shield | B7: onKill | C7: 击杀护盾·连坐豁免 | D7: 0.6 | E7: 2 | F7: =1 - (1-D7)^E7 | G7: +5 护盾
A8: blastKill | B8: onKill | C8: 连锁裁员·尸爆传染 | D8: 0.4 | E8: 2 | F8: =1 - (1-D8)^E8 | G8: 15 伤害 60px
A9: thornsHurt | B9: onHurt | C9: 复仇圆环·法务函件 | D9: 1 | E9: 3 | F9: =1 - (1-D9)^E9 | G9: 反弹 30%/层 | H9: 100% 触发

Sheet 消耗品
A1: ID | B1: 名称 | C1: 效果 | D1: 备注
A2: iced_americano | B2: 冰美式续命水 | C2: 回复 30 HP
A3: overtime_redbull | B3: 加班红牛 | C3: 5秒 移速 +50%
A4: stock_option | B4: 期权空头支票 | C4: +50 经验
A5: n1_package | B5: N+1大礼包 | C5: 30 护盾(10s)
A6: teambuild_milktea | B6: 团建奶茶 | C6: 8s 射速 +30%
A7: boss_pie | B7: 老板画的饼 | C7: 50% 回25HP / 50% 啥没有
A8: double_quota | B8: 双倍配额卡 | C8: 6s 射速×1.5 | D8: v18 修正
A9: reset_card | B9: 重置卡 | C9: 全部冷却清零
A10: n2_package | B10: 2N 大礼包 | C10: 60 护盾(12s)+回20HP
A11: resume_refresh | B11: 简历刷新卡 | C11: +1 三选一免费重抽

Sheet 觉醒配方
A1: ID | B1: 名称 | C1: persona | D1: 前置技能 | E1: 前置搭档 | F1: 效果
A2: evo_blame_furnace | B2: 无限连坐熔炉 | C2: optimizer | D2: 甩锅式反伤(紫满级) | E2: 熔断机制(蓝满级) | F2: 转移概率 40%→80%
A3: evo_dismissal_committee | B3: 永续裁员委员会 | C3: optimizer | D3: 末位淘汰制(紫满级) | E3: 花名册连坐 | F3: 连坐锁链全场+15%移速+10%伤害
A4: evo_online_offline | B4: 在线但心已离职 | C4: slacker | D4: 永动摸鱼引擎(橙满级) | E4: 临时下线 | F4: 高铁摸鱼期命中叠永久+1%攻击，上限15层
A5: evo_pretend_not_seen | B5: 被优化了但我假装没看见 | C5: slacker | D5: 假勤奋真怠工(紫满级) | E5: 在线状态徽章 | F5: 触发8s→5s + 2s内35%忽视伤害

Sheet 精英怪
A1: ID | B1: 名称 | C1: tier | D1: HP | E1: 移速 | F1: 触碰 | G1: 等级 | H1: 特殊
A2: hallu | B2: 幻觉体 | C2: 1 | D2: 45 | E2: 185 | F2: 6 | G2: 3 | H2: 触碰施幻觉6s
A3: overfit | B3: 过拟合壮汉 | C3: 1 | D3: 320 | E3: 52 | F3: 18 | G3: 5 | H3: 触碰施过拟合7s
A4: injector | B4: 提示注入者 | C4: 1 | D4: 70 | E4: 115 | F4: 0 | G4: 4 | H4: 远程复读机/溢出弹
A5: align | B5: 对齐守卫 | C5: 1 | D5: 160 | E5: 78 | F5: 10 | G5: 4 | H5: 正面免疫子弹
A6: ppt | B6: PPT 大师 | C6: 2 | D6: 260 | E6: 70 | F6: 0 | G6: 6 | H6: 光锥+眩晕
A7: upman | B7: 向上管理大师 | C7: 2 | D7: 220 | E7: 95 | F7: 0 | G7: 6 | H7: 给周围光环+奶血
A8: snitch | B8: 小报告专家 | C8: 2 | D8: 150 | E8: 125 | F8: 0 | G8: 5 | H8: 举报被举报者被围殴
A9: meeting | B9: 会议发起人 | C9: 2 | D9: 200 | E9: 85 | F9: 0 | G9: 5 | H9: 日历圈减速掉血
A10: intern | B10: 卷王实习生 | C10: 2 | D10: 180 | E10: 90 | F10: 12 | G10: 5 | H10: 血低越猛
A11: attendance | B11: 考勤主管 | C11: 2 | D11: 240 | E11: 75 | F11: 0 | G11: 6 | H11: 黄圈预警高伤

Sheet 杂鱼
A1: ID | B1: 名称 | C1: HP | D1: 移速 | E1: 触碰 | F1: xp | G1: AI 品类 | H1: 月份
A2: email | B2: 未读邮件 | C2: 11 | D2: 105 | E2: 2.5 | F2: 1.6 | G2: 直线追击(5s升级) | H2: 1
A3: urgent_email | B3: 加急邮件 | C3: 13 | D3: 130 | E3: 3.7 | F3: 2 | G3: 升级版直线追击 | H3: email升级
A4: sticky | B4: 待办便利贴 | C4: 20 | D4: 60 | E4: 4 | F4: 2.2 | G4: 直线追击 | H4: 2
A5: cr | B5: 需求变更单 | C5: 14 | D5: 95 | E5: 3 | F5: 1.6 | G5: 抖动追击+死亡分裂 | H5: 3
A6: cc_bomb | B6: 抄送轰炸 | C6: 8 | D6: 130 | E6: 2 | F6: 1.5 | G6: 追击+3.5s发3追踪弹+死亡分裂 | H6: 1
A7: read_reply | B7: 已读不回 | C7: 3 | D7: 160 | E7: 1.5 | F7: 1 | G7: 分裂产物极速小杂鱼 | H7: 分裂
A8: reinvent_wheel | B8: 重复造轮子任务 | C8: 12 | D8: 55 | E8: 3 | F8: 2.5 | G8: 独立护盾5+破防1.2s硬直 | H8: 1
A9: meeting_invite | B9: 会议邀请 | C9: 22 | D9: 50 | E9: 3.5 | F9: 2.5 | G9: 8s改期消失+无敌 | H9: 2
A10: message_recall | B10: 已发送-撤回中 | C10: 12 | D10: 100 | E10: 2.5 | F10: 2 | G10: 死亡50%复活 | H10: 2
A11: urgent_meeting | B11: 加急会议提醒 | C11: 16 | D11: 45 | E11: 0 | F11: 3 | G11: 光圈dot+减速 | H11: 3
A12: outsourced_army | B12: 临时工外包大军 | C12: 5 | D12: 140 | E12: 1.5 | F12: 0.8 | G12: 6只一组合围+组奖励 | H12: 3
A13: overtime_rework | B13: 深夜返工提醒 | C13: 24 | D13: 85 | E13: 3.5 | F13: 3.5 | G13: 受伤攒值→冲刺→虚弱 | H13: 4
A14: kpi_hunter | B14: KPI 追杀者 | C14: 60 | D14: 118 | E14: 6 | F14: 8 | G14: 中间层直线追击 | H14: 3
A15: read_no_reply_ultimate | B15: 已读不回·终极形态 | C15: 45 | D15: 170 | E15: 2 | F15: 6 | G15: 极高闪避+全场最快 | H15: 5
A16: req_review_board | B16: 需求评审会 | C16: 45 | D16: 0 | E16: 0 | F16: 6 | G16: 据点型+加速光环 | H16: 4
A17: night_lamp | B17: 深夜加班灯 | C17: 8 | D17: 0 | E17: 0 | F17: 5 | G17: 静止+光照易伤 | H17: 2
A18: phishing_mail | B18: 钓鱼邮件(v18) | C18: 14 | D18: 90 | E18: 1.5 | F18: 3 | G18: 保距230px+发钓鱼链接减速 | H18: 1
A19: deadline_alarm | B19: 死线警报(v18) | C19: 16 | D19: 0 | E19: 0 | F19: 4 | G19: 站桩+5s玩家脚下爆炸12伤 | H19: 1

Sheet 失衡分析
A1: 基于场景参数的 DPS 与 bug 组合分析
A3: 一、每把武器满 build DPS vs Boss HP 生存时间
A4: 武器 | B4: kind | C4: 基础 DPS | D4: 满 build DPS | E4: 击杀 Boss 秒数 | F4: 击杀狂暴期秒数 | G4: 评估
A5: DeepSeek | B5: mg | C5: =主武器!I2 | D5: =主武器!N2 | E5: =IF(D5>0, boss_hp/D5, "N/A") | F5: =IF(D5>0, boss_hp*(1-boss_rageT)/D5, "N/A") | G5: =IF(ISNUMBER(F5), IF(F5<2, "⚠️狂暴期<2s被跳过", IF(F5<4, "偏快", "健康")), "非弹道类另评")
A6: Kimi | B6: sniper | C6: =主武器!I3 | D6: =主武器!N3 | E6: =IF(D6>0, boss_hp/D6, "N/A") | F6: =IF(D6>0, boss_hp*(1-boss_rageT)/D6, "N/A") | G6: =IF(ISNUMBER(F6), IF(F6<2, "⚠️狂暴期<2s被跳过", IF(F6<4, "偏快", "健康")), "非弹道类另评")
A7: 通义千问 | B7: shotgun | C7: =主武器!I4 | D7: =主武器!N4 | E7: =IF(D7>0, boss_hp/D7, "N/A") | F7: =IF(D7>0, boss_hp*(1-boss_rageT)/D7, "N/A") | G7: =IF(ISNUMBER(F7), IF(F7<2, "⚠️狂暴期<2s被跳过", IF(F7<4, "偏快", "健康")), "非弹道类另评")
A8: 文心一言 | B8: lob | C8: =主武器!I5 | D8: =主武器!N5 | E8: =IF(D8>0, boss_hp/D8, "N/A") | F8: =IF(D8>0, boss_hp*(1-boss_rageT)/D8, "N/A") | G8: =IF(ISNUMBER(F8), IF(F8<2, "⚠️狂暴期<2s被跳过", IF(F8<4, "偏快", "健康")), "非弹道类另评")
A9: 豆包 | B9: homing | C9: =主武器!I6 | D9: =主武器!N6 | E9: =IF(D9>0, boss_hp/D9, "N/A") | F9: =IF(D9>0, boss_hp*(1-boss_rageT)/D9, "N/A") | G9: =IF(ISNUMBER(F9), IF(F9<2, "⚠️狂暴期<2s被跳过", IF(F9<4, "偏快", "健康")), "非弹道类另评")
A10: 智谱GLM | B10: chain | C10: =主武器!I7 | D10: =主武器!N7 | E10: =IF(D10>0, boss_hp/D10, "N/A") | F10: =IF(D10>0, boss_hp*(1-boss_rageT)/D10, "N/A") | G10: =IF(ISNUMBER(F10), IF(F10<2, "⚠️狂暴期<2s被跳过", IF(F10<4, "偏快", "健康")), "非弹道类另评")
A11: ChatGPT | B11: single | C11: =主武器!I8 | D11: =主武器!N8 | E11: =IF(D11>0, boss_hp/D11, "N/A") | F11: =IF(D11>0, boss_hp*(1-boss_rageT)/D11, "N/A") | G11: =IF(ISNUMBER(F11), IF(F11<2, "⚠️狂暴期<2s被跳过", IF(F11<4, "偏快", "健康")), "非弹道类另评")
A12: Claude | B12: charge | C12: =主武器!I9 | D12: =主武器!N9 | E12: =IF(D12>0, boss_hp/D12, "N/A") | F12: =IF(D12>0, boss_hp*(1-boss_rageT)/D12, "N/A") | G12: =IF(ISNUMBER(F12), IF(F12<2, "⚠️狂暴期<2s被跳过", IF(F12<4, "偏快", "健康")), "非弹道类另评")
A13: Gemini | B13: twin | C13: =主武器!I10 | D13: =主武器!N10 | E13: =IF(D13>0, boss_hp/D13, "N/A") | F13: =IF(D13>0, boss_hp*(1-boss_rageT)/D13, "N/A") | G13: =IF(ISNUMBER(F13), IF(F13<2, "⚠️狂暴期<2s被跳过", IF(F13<4, "偏快", "健康")), "非弹道类另评")
A14: Copilot | B14: drone | C14: =主武器!I11 | D14: =主武器!N11 | E14: =IF(D14>0, boss_hp/D14, "N/A") | F14: =IF(D14>0, boss_hp*(1-boss_rageT)/D14, "N/A") | G14: =IF(ISNUMBER(F14), IF(F14<2, "⚠️狂暴期<2s被跳过", IF(F14<4, "偏快", "健康")), "非弹道类另评")
A15: Midjourney | B15: gacha | C15: =主武器!I12 | D15: =主武器!N12 | E15: =IF(D15>0, boss_hp/D15, "N/A") | F15: =IF(D15>0, boss_hp*(1-boss_rageT)/D15, "N/A") | G15: =IF(ISNUMBER(F15), IF(F15<2, "⚠️狂暴期<2s被跳过", IF(F15<4, "偏快", "健康")), "非弹道类另评")
A16: Grok | B16: boomerang | C16: =主武器!I13 | D16: =主武器!N13 | E16: =IF(D16>0, boss_hp/D16, "N/A") | F16: =IF(D16>0, boss_hp*(1-boss_rageT)/D16, "N/A") | G16: =IF(ISNUMBER(F16), IF(F16<2, "⚠️狂暴期<2s被跳过", IF(F16<4, "偏快", "健康")), "非弹道类另评")
... A21: 百川智能(v18) | B21: field | C21: =主武器!I18 | D21: =主武器!N18 | E21: =IF(D21>0, boss_hp/D21, "N/A") | F21: =IF(D21>0, boss_hp*(1-boss_rageT)/D21, "N/A") | G21: =IF(ISNUMBER(F21), IF(F21<2, "⚠️狂暴期<2s被跳过", IF(F21<4, "偏快", "健康")), "非弹道类另评")
A24: 二、Proc 复合触发率——同时装满 8 种附魔（onHit + onCrit + onKill + onHurt）
A25: hook | B25: 单效果满级触发率 | C25: 同 hook 独立效果数 | D25: 至少一个触发概率 | E25: 备注
A26: onHit | B26: 0.2 | C26: 3 | D26: =1 - (1-B26)^C26 | E26: 火焰附魔
A27: onHit | B27: 0.25 | C27: 3 | D27: =1 - (1-B27)^C27 | E27: 冰霜附魔
A28: onHit | B28: 0.3 | C28: 3 | D28: =1 - (1-B28)^C28 | E28: 毒液附魔
A29: onHit | B29: 0.5 | C29: 3 | D29: =1 - (1-B29)^C29 | E29: 吸血附魔
A30: onCrit | B30: 0.4 | C30: 3 | D30: =1 - (1-B30)^C30 | E30: 雷电附魔
A31: onKill | B31: 0.6 | C31: 2 | D31: =1 - (1-B31)^C31 | E31: 击杀护盾
A32: onKill | B32: 0.4 | C32: 2 | D32: =1 - (1-B32)^C32 | E32: 尸爆
A33: onHurt | B33: 1 | C33: 3 | D33: =1 - (1-B33)^C33 | E33: 复仇圆环
A35: onHit 类满级 4 张同装 → 至少一个触发概率(独立事件) | D35: =1 - (1-D26)*(1-D27)*(1-D28)*(1-D29) | E35: ⚠️ 若>=90% 意味着每一发子弹都必然触发多种附魔效果
A37: 三、v18 修正后 破局技能 等效 DPS（是否仍溢出）
A38: 技能 | B38: 触发方式 | C38: 目标数 | D38: 单次总伤害 | E38: 触发周期(s) | F38: 等效 DPS | G38: 与武器 DPS 对比 | H38: 评估
A39: 假勤奋真怠工(v18池) | B39: 不受伤8s触发 | C39: 15 | D39: =15 * MIN(pl_dmg*10*3, pl_dmg*10*8/15) | E39: 8 | F39: =IF(E39>0, D39/E39, D39) | G39: =F39 / 主武器!N8 | H39: =IF(G39>=1.0, "⚠️相当于额外一把满build武器", IF(G39>=0.5, "值得注意", "已修正"))
A40: 永动摸鱼引擎(v18) | B40: 移800px触发 | C40: 3 | D40: =pl_dmg*10*0.6 * 5 * 2 * 3 | E40: 12 | F40: =IF(E40>0, D40/E40, D40) | G40: =F40 / 主武器!N8 | H40: =IF(G40>=1.0, "⚠️相当于额外一把满build武器", IF(G40>=0.5, "值得注意", "已修正"))
A41: 末位淘汰制(v18 cap 250) | B41: 每8s一次 | C41: 3 | D41: =250 * 3 | E41: 8 | F41: =IF(E41>0, D41/E41, D41) | G41: =F41 / 主武器!N8 | H41: =IF(G41>=1.0, "⚠️相当于额外一把满build武器", IF(G41>=0.5, "值得注意", "已修正"))
A42: 全员大会核爆 | B42: 30积分触发 | C42: 10 | D42: =pl_dmg*10*3.5 * 10 | E42: 30 | F42: =IF(E42>0, D42/E42, D42) | G42: =F42 / 主武器!N8 | H42: =IF(G42>=1.0, "⚠️相当于额外一把满build武器", IF(G42>=0.5, "值得注意", "已修正"))
A43: 甩锅式反伤觉醒 | B43: 受伤转移 | C43: 1 | D43: =pl_dmg*10*20*0.8*1.5 | E43: 5 | F43: =IF(E43>0, D43/E43, D43) | G43: =F43 / 主武器!N8 | H43: =IF(G43>=1.0, "⚠️相当于额外一把满build武器", IF(G43>=0.5, "值得注意", "已修正"))
A46: 四、Boss 战总时长（v18 前后）
A47: 阶段 | B47: Boss HP | C47: 玩家 DPS | D47: 击杀秒数 | E47: v18 修正后 | F47: 设计意图 | G47: 评估
A48: v16(旧) 满 build vs Boss | B48: 4360 | C48: 2000 | D48: =B48/C48 | E48: — | F48: 应有第二阶段 | G48: ⚠️狂暴期 1-2 秒被跳过
A49: v18(新) 满 build vs Boss | B49: =boss_hp | C49: 2000 | D49: =B49/C49 | E49: =B49*(1-boss_rageT)/(C49*boss_dmgTakenRage) + boss_shieldPct*B49/(C49*boss_dmgTakenRage) | F49: 狂暴期 3-5 秒 | G49: =IF(E49>=3, "健康", "仍偏快")
A51: 五、已知设计缺口 & bug 组合汇总
A52: # | B52: 类别 | C52: 组合/内容 | D52: 影响 | E52: 严重程度 | F52: 建议
...

Sheet 公式发现的Bug
A1: 公式驱动分析发现的失衡（v18 现状，非设计文档已列的）
A3: # | B3: 类别 | C3: Bug | D3: 公式代入数字 | E3: 影响 | F3: 严重度 | G3: 建议修法 | H3: v18 修复状态
A4: 1 | B4: 主武器超模 | C4: MiniMax(totem) 满 build DPS = 2992 (第 1 名)——超过 Claude 71% | D4: 3 × 8dmg × 2.856 lvlMult × 2.167 pl_dmg × 2.466 echo × 1.57 crit × 2.862 fireRateOf / 0.55 shotCd = 2992 | E4: 成为最强主武器；3 座炮台叠加时输出爆炸 | F4: ⚠️高 | G4: 炮台 shotCd 0.55→0.8 或 base dmg 8→5，或 maxDeploy 3→2；配合 lvlMult 特殊处理 | H4: ✅ v18: MiniMax dmg 8→6 shotCd 0.55→0.75
A5: 2 | B5: 主武器超模 | C5: 月之暗面(mine) 满 build DPS = 2469 (第 2 名) | D5: 18dmg × 2.856 × 2.167 × 2.466 × 1.57 × 2.862 / 0.5 cd = 2469 (100% 触发假设) | E5: 当敌人成群走过雷区(触发率高)时爆炸；实际约 30-50% 触发 | F5: 中 | G5: 实测触发率若>60% 需调低 base dmg 18→12 或提升 cd 0.5→0.8 | H5: ✅ v18: 月之暗面 dmg 18→12 cd 0.5→0.8
A6: 3 | B6: 主武器欠弱 | C6: Copilot(drone) 满 build DPS = 446 (第 16 名)——只有 Claude 的 26% | D6: 8.5 × 1.749 (drone lvlMult 1.15^4) × 2.167 × 2.466 × 1.57 × 2.862 / 0.8 = 446 | E6: 飞机流永远比其他 build 弱 | F6: 中 | G6: drone lvlMult 1.15→1.22 或 base dmg 8.5→12；或允许 drone 计 fireRate 之外的加成 | H6: ✅ v18: drone grow 1.15→1.2 (Lv.5 lvlMult 2.074)
A7: 4 | B7: 主武器欠弱 | C7: 百川智能(field) DPS = 214 (第 17 名，垫底) | D7: 22 dps × 2.167 pl_dmg × 2.856 lvlMult × 1.57 crit = 214 per target | E7: 燃烧场地虽然可覆盖但对单体 Boss 无优势 | F7: 低 | G7: field dps 22→35 或允许 field 也吃 multishot×echo 效果 | H7: ⏭️ v18: field dps 22→32 且吃 lvlMult
A8: 5 | B8: 传说武器整体欠弱 | C8: 所有 6 传说 DPS = 82-327，普通武器 Lv.5 是 720-1745——玩家融合传说反而变弱 | D8: 传说 lvlMult=1 (硬编码 wpnDmg 里)，无法吃 1.3^4=2.856 倍加成；差距 2.86 倍 | E8: 融合系统的设计目的被彻底反转——玩家会拒绝融合 | F8: ⚠️极高 | G8: 选一：(A) 传说也吃 lvlMult 但融合后 lvl 归 1；(B) 传说 base dmg 全部 ×2.5；(C) 融合时把 lvlMult 一次性固定在 2.856 | H8: ⏭️ 未修：需 legendary lvlMult 系统性重设(风险高)
A9: 6 | B9: Proc 组合失衡 | C9: onHit 类 4 张(火+冰+毒+吸血) 满级同装 → 每发子弹至少触发一种附魔 = 99.1% | D9: 1 - (1-0.488)(1-0.578)(1-0.657)(1-0.875) = 0.991 | E9: "随机触发"变成"必然触发"，附魔的"随机稀有感"消失 | F9: ⚠️高 | G9: 给同 hook 类 procs 加"整体触发上限 60%"，或让互斥/共享冷却 | H9: ✅ v18: onHit 元素类每次命中最多 1 触发
A10: 7 | B10: Proc 触发率异常 | C10: 雷电附魔满级触发率 78.4% × 玩家 crit 57% = 44.7%/发 | D10: (1-(1-0.4)^3) × 0.57 = 0.447；DeepSeek 26 shots/sec × 26.2 dmg/触发 = 304 DPS 额外 | E10: 雷电附魔单张卡就贡献 300+ DPS，是紫色技能的强度 | F10: 中 | G10: 雷电基础触发率 40%/层 → 25%/层 (满级 57.8%)；或雷电独立冷却 0.5s | H10: ✅ v18: 基础 40%→25%/层
A11: 8 | B11: Proc 语义错误 | C11: 复仇圆环 chance=1.0 时 3 层各自 100% 触发，累计反弹 90% 伤害 | D11: 3 × 30% = 90% 反弹，玩家近战流几乎不用还手 | E11: 受伤反弹机制过强，让"输出反伤流"成为最优解 | F11: ⚠️高 | G11: 把 chance=1.0 改为分层递减(1.0/0.7/0.5)，或直接改为"叠加 pct，同一 hit 只触发一次" | H11: ✅ v18: 3 层 pct 合并到单 proc
A12: 9 | B12: Boss 血量公式 | C12: 当前 Boss HP = 9750 (Lv.15 满 build)，玩家 Claude DPS 1745 | D12: 9750 / 1745 = 5.59s 击杀；狂暴期约 1745×0.7×0.15/0.7= 261 blocked，实战 4.22s 狂暴期 | E12: 狂暴期存在但 Claude 玩家可能仍太快 | F12: 中 | G12: 考虑 Boss HP 系数再抬 10%，或狂暴期 dmgTaken 0.7→0.55 | H12: ⏭️ v18 Fix 1 已修 (Boss HP + 狂暴前置)
A13: 10 | B13: 副武器输出偏低 | C13: 副武器 Lv.3 最高 DPS = 显示器回旋盾 18 | D13: 与主武器 1000+ DPS 对比，副武器仅占总输出 1.5% | E13: 副武器变成"装饰品"而非"构筑决定" | F13: 低 | G13: 副武器 dmg 值整体 ×2；或副武器也吃 lvlMult 系数 | H13: ⏭️ 副武器补强留待后续 (低优先级)
